Workbook

Sheet COSTO TOTAL
A1: MES | B1: (Todas)
A3: COSTOS | B3: Etiquetas de columna
A4: Etiquetas de fila | B4: CATERPILLAR 1 | C4: NISSAN 7 | D4: TOYOTA 10 | E4: TOYOTA 11 | F4: TOYOTA 12 | G4: TOYOTA 13 | H4: TOYOTA 5 | I4: TOYOTA 8 | J4: TOYOTA 9 | K4: (en blanco) | L4: TOTAL COSTO
A5: OK | B5: 5370150 | C5: 2052100 | D5: 1558000 | E5: 21239234 | F5: 14811574 | G5: 2859800 | H5: 19563994 | I5: 25724227 | J5: 7594239 | L5: 100773318
A6: (en blanco) | F6: 1035000 | J6: 4796000 | L6: 5831000
A7: TOTAL COSTO | B7: 5370150 | C7: 2052100 | D7: 1558000 | E7: 21239234 | F7: 15846574 | G7: 2859800 | H7: 19563994 | I7: 25724227 | J7: 12390239 | L7: 106604318

Sheet DATA
A1: FECHA | B1: EQUIPO | C1: SISTEMA | D1: TIEMPO | E1: NOVEDAD | F1: REPUESTOS | G1: No. COTIZACION | H1: PROCESO | I1: HOROMETRO | J1: COSTO | K1: PREVENTIVO | L1: MES | M1: AÑO
A2: 45748 | B2: CATERPILLAR 1 | C2: ENCENDIDO | D2: 8 | E2: PROBLEMA DE ENCENDIDO, SE LE CAMBIA BOBINA | F2: 01 BOBINA | L2: =MONTH(A2) -> 4 | M2: =YEAR(Tabla1[[#This Row],[FECHA]]) -> 2025
A3: 45748 | B3: TOYOTA 8 | C3: DIRECCION | D3: 7 | E3: FRENOS ROTOS DE LA RUEDA TRASERA, SE LE CAMBIA SEIS (6) PERNOS | F3: 06 PERNOS | L3: =MONTH(A3) -> 4 | M3: =YEAR(Tabla1[[#This Row],[FECHA]]) -> 2025
A4: 45749 | B4: CATERPILLAR 1 | C4: ENCENDIDO | D4: 36 | E4: PROBLEMAS EN ARRANQUE SALE PARA REPARACION | F4: 04 ESCOBILLAS, 02 RODAMIENTOS, 01 AUTOMATICO | L4: =MONTH(A4) -> 4 | M4: =YEAR(Tabla1[[#This Row],[FECHA]]) -> 2025
A5: 45749 | B5: TOYOTA 9 | C5: ENCENDIDO | D5: 7 | E5: SE EVIDENCIA PROBLEMAS DE ENCENDIDO, SE REALIZA INTERCAMBIO DE BOBINAS CON LA 8 | F5: 01 BOBINA | L5: =MONTH(A5) -> 4 | M5: =YEAR(Tabla1[[#This Row],[FECHA]]) -> 2025
A6: 45754 | B6: TOYOTA 9 | C6: MTTO PREVENTIVO | D6: 7 | E6: ENTRA AL TALLER POR BAJO NIVEL ACEITE MOTOR, SE LE REALIZA MANTENIMIENTO PREVENTIVO. | F6: 01 FILTRO ACEITE, 02 FILTRO DE AIRE, 01 ACEITE MOTOR, 01 GRASA HH S 500, 01 LUB DE CADENA | L6: =MONTH(A6) -> 4 | M6: =YEAR(Tabla1[[#This Row],[FECHA]]) -> 2025
A7: 45757 | B7: CATERPILLAR 1 | C7: TRACCION | D7: 8 | E7: EQUIPO VARADO EN TALLER POR MARCHAS, SE CAMBIA ELECTROVALVULA DE MARCHAS QUEDA OPERATIVA | F7: 01 ELECROVALVULA DE MARCHAS | L7: =MONTH(A7) -> 4 | M7: =YEAR(Tabla1[[#This Row],[FECHA]]) -> 2025
A8: 45758 | B8: TOYOTA 12 | C8: ENCENDIDO | D8: 53 | E8: FALLA DISTTRIBUIDOR DE CORRIENTE | F8: 01 DISTRIBUIDOR DE CORRIENTE | L8: =MONTH(A8) -> 4 | M8: =YEAR(Tabla1[[#This Row],[FECHA]]) -> 2025
A9: 45759 | B9: TOYOTA 11 | C9: MASTIL | D9: 5 | E9: TORNILLOS DEL DESPLAZADOR LATERAL ROTO | F9: 01 TORNILLOS | L9: =MONTH(A9) -> 4 | M9: =YEAR(Tabla1[[#This Row],[FECHA]]) -> 2025
A10: 45762 | B10: TOYOTA 11 | C10: FRENOS | D10: 1 | E10: SE LE CALIBRAN FRENOS, QUEDA OPERATIVA | L10: =MONTH(A10) -> 4 | M10: =YEAR(Tabla1[[#This Row],[FECHA]]) -> 2025
A11: 45764 | B11: TOYOTA 8 | C11: TRACCION | D11: 6 | E11: SE CORRIGE FUGA ACEITE TRANSMISION | F11: 04 ORING | L11: =MONTH(A11) -> 4 | M11: =YEAR(Tabla1[[#This Row],[FECHA]]) -> 2025
A12: 45765 | B12: TOYOTA 8 | C12: FRENOS | D12: 80 | E12: EQUIPO FUERA DE SERVICIO POR FALLA DE FRENOS | F12: 04 BANDAS,02 RETENEDOPRES CAMPANAS, 02 RETENEDORES EJE, 02 TENSOR BANDAS | I12: 44070 | L12: =MONTH(A12) -> 4 | M12: =YEAR(Tabla1[[#This Row],[FECHA]]) -> 2025
A13: 45765 | B13: TOYOTA 9 | C13: SIST. HIDRAULICO | D13: 5 | E13: CAMBIO DE MANGUERAS, SISTEMA HIDRAULICO | F13: 01 MANGUERAS | L13: =MONTH(A13) -> 4 | M13: =YEAR(Tabla1[[#This Row],[FECHA]]) -> 2025
A14: 45765 | B14: TOYOTA 10 | C14: TRACCION | D14: 5 | E14: FUGA DE ACEITE POR EJE, SE RETIRA VINIPEL Y SE ENTREGA OPERATIVA. | F14: 01 SILICONA ULTRAGADE | L14: =MONTH(A14) -> 4 | M14: =YEAR(Tabla1[[#This Row],[FECHA]]) -> 2025
A15: 45768 | B15: TOYOTA 11 | C15: FRENOS | D15: 2 | E15: SE CALIBRAN LOS FRENOS Y SE REGULO LA ACELERACION | L15: =MONTH(A15) -> 4 | M15: =YEAR(Tabla1[[#This Row],[FECHA]]) -> 2025
A16: 45769 | B16: TOYOTA 9 | C16: DIRECCION | D16: 2 | E16: PERNOS ROTOS, SE REALIZO CAMBIO, EQUIPO OPERATIVO | F16: 06 PERNOS | L16: =MONTH(A16) -> 4 | M16: =YEAR(Tabla1[[#This Row],[FECHA]]) -> 2025
A17: 45771 | B17: TOYOTA 8 | C17: COMBUSTIBLE | D17: 24 | E17: VARADA POR SISTEMA LPG | F17: 01 EMPAQUETADURA DEL FILTRO, VAPORIZADOR, 01 MEZCLADOR | L17: =MONTH(A17) -> 4 | M17: =YEAR(Tabla1[[#This Row],[FECHA]]) -> 2025
A18: 45771 | B18: TOYOTA 9 | C18: COMBUSTIBLE | D18: 4 | E18: CILINDRO DE GAS VACIO, EQUIPO OPERATIVO | L18: =MONTH(A18) -> 4 | M18: =YEAR(Tabla1[[#This Row],[FECHA]]) -> 2025
A19: 45774 | B19: TOYOTA 8 | C19: FRENOS | D19: 3 | E19: MAQUINA VARADA POR FRENOS, SE LE CAMBIA BOMBA PARA LOS FRENOS | F19: 01 BOMBA DE FRENOS | I19: 44110 | L19: =MONTH(A19) -> 4 | M19: =YEAR(Tabla1[[#This Row],[FECHA]]) -> 2025
A20: 45774 | B20: TOYOTA 9 | C20: SIST. HIDRAULICO | D20: 4 | E20: MAQUINA VARADA POR UNA MANGUERA SUELTA, EQUIPO OPERATIVO | L20: =MONTH(A20) -> 4 | M20: =YEAR(Tabla1[[#This Row],[FECHA]]) -> 2025
A21: 45775 | B21: TOYOTA 9 | C21: DIRECCION | D21: 3 | E21: RUEDA TRASERA SUELTA POR DAÑO EN RIN, SE AJUSTAN TUERCAS, EQUIPO OPERATIVO | L21: =MONTH(A21) -> 4 | M21: =YEAR(Tabla1[[#This Row],[FECHA]]) -> 2025
A22: 45777 | B22: TOYOTA 9 | C22: MASTIL | D22: 1 | E22: DAÑO EN LOS DESLIZADORES INFERIORES DEL CARRO PORTAHORQUILLAS, EQUIPO OPERATIVO | F22: 02 DESLIZADORES | L22: =MONTH(A22) -> 4 | M22: =YEAR(Tabla1[[#This Row],[FECHA]]) -> 2025
A23: 45778 | B23: TOYOTA 11 | C23: TRACCION | D23: 432 | E23: EQUIPO FUERA DE SERVICIO POR TRANSMISION AUTOMATICA | F23: (1) WIRE ASSEMBLY INCHING, (1) WIRE-SOLENOID, (1) FILTER TRANSMISIÓN, (2) HOSE- LOW PRESSURE, (1) SEAL KIT-TRANSMISSION, (1) SEAL KIT-TRANSMISSION, (10) PLATE -STEEL CLUTCH, (10) DISCO EMBRAGUE HIDRAULICO, (02) BANDAS FRENOS, (01) SEAL-OIL RUBBER, (1) HUB OIL SEAL METAL, (8) DEXRON III ACEITE TRANSMISIÓN Y DIRECCIÓN 1/4, (1) LIQUIDO DE FRENOS DOT4 | L23: =MONTH(A23) -> 5 | M23: =YEAR(Tabla1[[#This Row],[FECHA]]) -> 2025
A24: 45782 | B24: TOYOTA 9 | C24: SIST. HIDRAULICO | D24: 4 | E24: NOVEDAD EN LA BOMBA HD SE TOMA DE LA TY No. 11 Y CAMBIO DEL ACEITE POR MEZCLA CON EL DE MOTOR | F24: 01 BOMBA HIDRAULICA, 10 GALONES ACEITE HD ISO 68 | L24: =MONTH(A24) -> 5 | M24: =YEAR(Tabla1[[#This Row],[FECHA]]) -> 2025
A25: 45786 | B25: TOYOTA 13 | C25: POTENCIA | D25: 3 | E25: NOVEDAD EN EL CARGADOR DE LA BATERÍA. SE REPARA CABLEADO DEL CARGADOR POR DETERIORO. | L25: =MONTH(A25) -> 5 | M25: =YEAR(Tabla1[[#This Row],[FECHA]]) -> 2025
A26: 45790 | B26: TOYOTA 8 | C26: TRACCION | D26: 3 | E26: PRESENTA NOVEDAD EN MARCHAS SE CAMBIA CONTROL DE MARCHAS POR EL DE LA TY No. 11 | L26: =MONTH(A26) -> 5 | M26: =YEAR(Tabla1[[#This Row],[FECHA]]) -> 2025
A27: 45792 | B27: TOYOTA 5 | C27: SEGURIDAD | D27: 1 | E27: NOVEDAD EN SISTEMA DE LUCES SE CAMBIA LUZ ESTOBER | F27: 01 LUZ ESTOBER | L27: =MONTH(A27) -> 5 | M27: =YEAR(Tabla1[[#This Row],[FECHA]]) -> 2025
A28: 45792 | B28: TOYOTA 8 | C28: SIST. HIDRAULICO | D28: 1 | E28: PRESENTA FUGA DE ACEITE SE REALIZO CAMBIO DE FILTRO RETORNO DEL HD | F28: 01 FILTRO RETORNO DEL HD | L28: =MONTH(A28) -> 5 | M28: =YEAR(Tabla1[[#This Row],[FECHA]]) -> 2025
A29: 45796 | B29: TOYOTA 8 | C29: FRENOS | D29: 1 | E29: NOVEDAD EN FRENO DE PARQUEO *SE HIZOCAMBIO GUAYA DEL FRENO DE PARQUEO SE TOMA DE LA TY No. 11 | I29: 44368 | L29: =MONTH(A29) -> 5 | M29: =YEAR(Tabla1[[#This Row],[FECHA]]) -> 2025
A30: 45798 | B30: CATERPILLAR 1 | C30: DIRECCION | D30: 3 | E30: PRESENTA NOVEDAD EN EL SISTEMA DE DIRECCION. SE CAMBIA RODAMIENTO AXIAL DEL CACHO. | F30: 01 RODAMIENTO AXIAL, 01 SPLINDER | L30: =MONTH(A30) -> 5 | M30: =YEAR(Tabla1[[#This Row],[FECHA]]) -> 2025
A31: 45798 | B31: TOYOTA 8 | C31: TRACCION | D31: 1 | E31: PRESENTA FUGA DE ACEITE INSPECCION DE FUGA POR EL RETENEDOR DEL CARDAN | L31: =MONTH(A31) -> 5 | M31: =YEAR(Tabla1[[#This Row],[FECHA]]) -> 2025
A32: 45801 | B32: TOYOTA 10 | C32: TRACCION | D32: 41 | E32: EQUIPO INOPERATIVO *NOVEDAD EN RUEDA IZQUIERDA *SE REALIZA SOLDADURA AL RIN | L32: =MONTH(A32) -> 5 | M32: =YEAR(Tabla1[[#This Row],[FECHA]]) -> 2025
A33: 45803 | B33: TOYOTA 9 | C33: ENCENDIDO | D33: 6 | E33: NOVEDAD EN EL ENCENDIDO. *EQUIPO OPERATIVO SE LE CAMBIA EMPAQUETADURA Y MEZCLADOR COMPLETO. | F33: 01 EMPAQUETADURA, 01 MEZCLADOR | L33: =MONTH(A33) -> 5 | M33: =YEAR(Tabla1[[#This Row],[FECHA]]) -> 2025
A34: 45804 | B34: TOYOTA 12 | C34: SEGURIDAD | D34: 1 | E34: LUZ ESTROBER NO FUNCIONA, SE REALIZA CAMBIO DE LA LUZ AVERIADA | F34: 01 LUZ ESTROBER | I34: 17496 | J34: 120000 | L34: =MONTH(A34) -> 5 | M34: =YEAR(Tabla1[[#This Row],[FECHA]]) -> 2025
A35: 45804 | B35: TOYOTA 10 | C35: MASTIL | D35: 10 | E35: NOVEDAD EN EL MÁSTIL *SE RECTIFICAN ROSCAS DEL RESPALDO DE CARGA E INSTALAN TORNILLOS | F35: 04 TORNILLOS | L35: =MONTH(A35) -> 5 | M35: =YEAR(Tabla1[[#This Row],[FECHA]]) -> 2025
A36: 45806 | B36: TOYOTA 8 | C36: TRACCION | D36: 24 | E36: PRESENTA FUGA POR RETENEDOR DEL CARDÁN (DIFERENCIAL) SE TOMA BOBINA DEL DISTRIBUIDOR PARA HABILITAR TY No. 09 | F36: 01 RETENEDOR DE CARDAN, 01 DISTRIBUIDOR | L36: =MONTH(A36) -> 5 | M36: =YEAR(Tabla1[[#This Row],[FECHA]]) -> 2025
A37: 45806 | B37: TOYOTA 9 | C37: ENCENDIDO | D37: 3 | E37: NOVEDAD EN EL ENCENDIDO REPARACIÓN DEL DISTRIBUIDOR DE CORRIENTE (SE TOMAN REPUESTOS DE LA TY 08). | L37: =MONTH(A37) -> 5 | M37: =YEAR(Tabla1[[#This Row],[FECHA]]) -> 2025
A38: 45807 | B38: TOYOTA 11 | C38: FRENOS | D38: 7 | E38: NOVEDAD EN LOS FRENOS *REPARACÓN FRENOS LADO IZQUIERDO | F38: 02 BANDAS FRENO, 01 RETENEDOR CAMPANA, 01 RETEDOR EJE | L38: =MONTH(A38) -> 5 | M38: =YEAR(Tabla1[[#This Row],[FECHA]]) -> 2025
A39: 45804 | C39: SEGURIDAD | D39: 1 | E39: SE INSTALA LUZ ESTOBER A LA TY No.12 (AVERIADA) | F39: 01 LUZ ESTOBER | L39: =MONTH(A39) -> 5 | M39: =YEAR(Tabla1[[#This Row],[FECHA]]) -> 2025
A40: 45811 | B40: TOYOTA 5 | C40: SIST. HIDRAULICO | D40: 3 | E40: NOVEDAD EN SISTEMA DE DIRECCIÓN CAMBIO DE CILINDRO POR FUGA INTERNA | F40: 01 KIT DE EMPAQUETADURA | L40: =MONTH(A40) -> 6 | M40: =YEAR(Tabla1[[#This Row],[FECHA]]) -> 2025
...

Sheet Hoja1
B1: Enero | C1: Febrero | D1: Marzo | E1: Abril | F1: Mayo | G1: Junio | H1: Julio | I1: Agosto | J1: Septiembre | K1: Octubre | L1: Noviembre | M1: Diciembre
A2: CATERPILLAR 1 | B2: =SUMIFS(DATA!$J1:$J183,DATA!$B1:$B183,$A1,DATA!$L1:$L183,#REF!) -> 0
A3: TOYOTA 5 | B3: =SUMIFS(DATA!$J3:$J183,DATA!$B3:$B183,$A3,DATA!$L3:$L183,B$1) -> 0
A4: NISSAN 7 | B4: =SUMIFS(DATA!$J4:$J183,DATA!$B4:$B183,$A4,DATA!$L4:$L183,B$1) -> 0
A5: TOYOTA 8 | B5: =SUMIFS(DATA!$J5:$J183,DATA!$B5:$B183,$A5,DATA!$L5:$L183,B$1) -> 0
A6: TOYOTA 9 | B6: =SUMIFS(DATA!$J6:$J183,DATA!$B6:$B183,$A6,DATA!$L6:$L183,B$1) -> 0
A7: TOYOTA 10 | B7: =SUMIFS(DATA!$J7:$J183,DATA!$B7:$B183,$A7,DATA!$L7:$L183,B$1) -> 0
A8: TOYOTA 11 | B8: =SUMIFS(DATA!$J8:$J183,DATA!$B8:$B183,$A8,DATA!$L8:$L183,B$1) -> 0
A9: TOYOTA 12 | B9: =SUMIFS(DATA!$J9:$J183,DATA!$B9:$B183,$A9,DATA!$L9:$L183,B$1) -> 0
A10: TOYOTA 13 | B10: =SUMIFS(DATA!$J10:$J183,DATA!$B10:$B183,$A10,DATA!$L10:$L183,B$1) -> 0

Sheet RESULTADOS
C2: INDICADORES DE GESTIÓN
B6: MES: | C6: 12
B8: MTTR | C8: =L14/L17 -> 13.2
B9: DISPONIBILIDAD | C9: =L18/L13 -> 0.96071429
B10: GENERAL
B12: EQUIPOS | C12: CATERPILLAR 1 | D12: TOYOTA 5 | E12: NISSAN 7 | F12: TOYOTA 8 | G12: TOYOTA 9 | H12: TOYOTA 10 | I12: TOYOTA 11 | J12: TOYOTA 12 | K12: TOYOTA 13 | L12: CONSOLIDADO
B13: PROGRAMADO | C13: 480 | D13: 480 | E13: 480 | F13: 480 | G13: 720 | H13: 720 | I13: 480 | J13: 720 | K13: 480 | L13: =SUM(C13:K13) -> 5040
B14: T. SUSP. AVERIAS (hs) | C14: =SUMIFS(DATA!$D$2:$D$183,DATA!$B$2:$B$183,RESULTADOS!C12,DATA!$L$2:$L$183,RESULTADOS!$C$6,DATA!$C$2:$C$183,"<>REP. PLANIFICADO",DATA!$C$2:$C$183,"<>MTTO PREVENTIVO") -> 11 | D14: =SUMIFS(DATA!$D$2:$D$183,DATA!$B$2:$B$183,RESULTADOS!D12,DATA!$L$2:$L$183,RESULTADOS!$C$6,DATA!$C$2:$C$183,"<>REP. PLANIFICADO",DATA!$C$2:$C$183,"<>MTTO PREVENTIVO") -> 1 | E14: =SUMIFS(DATA!$D$2:$D$183,DATA!$B$2:$B$183,RESULTADOS!E12,DATA!$L$2:$L$183,RESULTADOS!$C$6,DATA!$C$2:$C$183,"<>REP. PLANIFICADO",DATA!$C$2:$C$183,"<>MTTO PREVENTIVO") -> 0 | F14: =SUMIFS(DATA!$D$2:$D$183,DATA!$B$2:$B$183,RESULTADOS!F12,DATA!$L$2:$L$183,RESULTADOS!$C$6,DATA!$C$2:$C$183,"<>REP. PLANIFICADO",DATA!$C$2:$C$183,"<>MTTO PREVENTIVO") -> 47 | G14: =SUMIFS(DATA!$D$2:$D$183,DATA!$B$2:$B$183,RESULTADOS!G12,DATA!$L$2:$L$183,RESULTADOS!$C$6,DATA!$C$2:$C$183,"<>REP. PLANIFICADO",DATA!$C$2:$C$183,"<>MTTO PREVENTIVO") -> 2 | H14: =SUMIFS(DATA!$D$2:$D$183,DATA!$B$2:$B$183,RESULTADOS!H12,DATA!$L$2:$L$183,RESULTADOS!$C$6,DATA!$C$2:$C$183,"<>REP. PLANIFICADO",DATA!$C$2:$C$183,"<>MTTO PREVENTIVO") -> 0 | I14: =SUMIFS(DATA!$D$2:$D$183,DATA!$B$2:$B$183,RESULTADOS!I12,DATA!$L$2:$L$183,RESULTADOS!$C$6,DATA!$C$2:$C$183,"<>REP. PLANIFICADO",DATA!$C$2:$C$183,"<>MTTO PREVENTIVO") -> 125 | J14: =SUMIFS(DATA!$D$2:$D$183,DATA!$B$2:$B$183,RESULTADOS!J12,DATA!$L$2:$L$183,RESULTADOS!$C$6,DATA!$C$2:$C$183,"<>REP. PLANIFICADO",DATA!$C$2:$C$183,"<>MTTO PREVENTIVO") -> 12 | K14: =SUMIFS(DATA!$D$2:$D$183,DATA!$B$2:$B$183,RESULTADOS!K12,DATA!$L$2:$L$183,RESULTADOS!$C$6,DATA!$C$2:$C$183,"<>REP. PLANIFICADO",DATA!$C$2:$C$183,"<>MTTO PREVENTIVO") -> 0 | L14: =SUM(C14:K14) -> 198
B15: T. MANTENIMIENTO (hs) | C15: =SUMIFS(DATA!$D$2:$D$183,DATA!$B$2:$B$183,RESULTADOS!C12,DATA!$L$2:$L$183,RESULTADOS!$C$6,DATA!$C$2:$C$183,"MTTO PREVENTIVO")+SUMIFS(DATA!$D$2:$D$183,DATA!$B$2:$B$183,RESULTADOS!C12,DATA!$L$2:$L$183,RESULTADOS!$C$6,DATA!$C$2:$C$183,"REP. PLANIFICADO") -> 4 | D15: =SUMIFS(DATA!$D$2:$D$183,DATA!$B$2:$B$183,RESULTADOS!D12,DATA!$L$2:$L$183,RESULTADOS!$C$6,DATA!$C$2:$C$183,"MTTO PREVENTIVO")+SUMIFS(DATA!$D$2:$D$183,DATA!$B$2:$B$183,RESULTADOS!D12,DATA!$L$2:$L$183,RESULTADOS!$C$6,DATA!$C$2:$C$183,"REP. PLANIFICADO") -> 10 | E15: =SUMIFS(DATA!$D$2:$D$183,DATA!$B$2:$B$183,RESULTADOS!E12,DATA!$L$2:$L$183,RESULTADOS!$C$6,DATA!$C$2:$C$183,"MTTO PREVENTIVO")+SUMIFS(DATA!$D$2:$D$183,DATA!$B$2:$B$183,RESULTADOS!E12,DATA!$L$2:$L$183,RESULTADOS!$C$6,DATA!$C$2:$C$183,"REP. PLANIFICADO") -> 0 | F15: =SUMIFS(DATA!$D$2:$D$183,DATA!$B$2:$B$183,RESULTADOS!F12,DATA!$L$2:$L$183,RESULTADOS!$C$6,DATA!$C$2:$C$183,"MTTO PREVENTIVO")+SUMIFS(DATA!$D$2:$D$183,DATA!$B$2:$B$183,RESULTADOS!F12,DATA!$L$2:$L$183,RESULTADOS!$C$6,DATA!$C$2:$C$183,"REP. PLANIFICADO") -> 6 | G15: =SUMIFS(DATA!$D$2:$D$183,DATA!$B$2:$B$183,RESULTADOS!G12,DATA!$L$2:$L$183,RESULTADOS!$C$6,DATA!$C$2:$C$183,"MTTO PREVENTIVO")+SUMIFS(DATA!$D$2:$D$183,DATA!$B$2:$B$183,RESULTADOS!G12,DATA!$L$2:$L$183,RESULTADOS!$C$6,DATA!$C$2:$C$183,"REP. PLANIFICADO") -> 4 | H15: =SUMIFS(DATA!$D$2:$D$183,DATA!$B$2:$B$183,RESULTADOS!H12,DATA!$L$2:$L$183,RESULTADOS!$C$6,DATA!$C$2:$C$183,"MTTO PREVENTIVO")+SUMIFS(DATA!$D$2:$D$183,DATA!$B$2:$B$183,RESULTADOS!H12,DATA!$L$2:$L$183,RESULTADOS!$C$6,DATA!$C$2:$C$183,"REP. PLANIFICADO") -> 4 | I15: =SUMIFS(DATA!$D$2:$D$183,DATA!$B$2:$B$183,RESULTADOS!I12,DATA!$L$2:$L$183,RESULTADOS!$C$6,DATA!$C$2:$C$183,"MTTO PREVENTIVO")+SUMIFS(DATA!$D$2:$D$183,DATA!$B$2:$B$183,RESULTADOS!I12,DATA!$L$2:$L$183,RESULTADOS!$C$6,DATA!$C$2:$C$183,"REP. PLANIFICADO") -> 8 | J15: =SUMIFS(DATA!$D$2:$D$183,DATA!$B$2:$B$183,RESULTADOS!J12,DATA!$L$2:$L$183,RESULTADOS!$C$6,DATA!$C$2:$C$183,"MTTO PREVENTIVO")+SUMIFS(DATA!$D$2:$D$183,DATA!$B$2:$B$183,RESULTADOS!J12,DATA!$L$2:$L$183,RESULTADOS!$C$6,DATA!$C$2:$C$183,"REP. PLANIFICADO") -> 8 | K15: =SUMIFS(DATA!$D$2:$D$183,DATA!$B$2:$B$183,RESULTADOS!K12,DATA!$L$2:$L$183,RESULTADOS!$C$6,DATA!$C$2:$C$183,"MTTO PREVENTIVO")+SUMIFS(DATA!$D$2:$D$183,DATA!$B$2:$B$183,RESULTADOS!K12,DATA!$L$2:$L$183,RESULTADOS!$C$6,DATA!$C$2:$C$183,"REP. PLANIFICADO") -> 0 | L15: =SUM(C15:K15) -> 44
B16: T. TOTAL SUSPEND (hs) | C16: =+SUMIFS(DATA!$D$2:$D$183,DATA!$B$2:$B$183,RESULTADOS!C12,DATA!$L$2:$L$183,RESULTADOS!$C$6,DATA!$C$2:$C$183,"REP. PROGRAMADO") -> 0 | D16: =SUMIFS(DATA!$D$2:$D$183,DATA!$B$2:$B$183,RESULTADOS!D12,DATA!$L$2:$L$183,RESULTADOS!$C$6) -> 11 | E16: =SUMIFS(DATA!$D$2:$D$183,DATA!$B$2:$B$183,RESULTADOS!E12,DATA!$L$2:$L$183,RESULTADOS!$C$6) -> 0 | F16: =SUMIFS(DATA!$D$2:$D$183,DATA!$B$2:$B$183,RESULTADOS!F12,DATA!$L$2:$L$183,RESULTADOS!$C$6) -> 53 | G16: =SUMIFS(DATA!$D$2:$D$183,DATA!$B$2:$B$183,RESULTADOS!G12,DATA!$L$2:$L$183,RESULTADOS!$C$6) -> 6 | H16: =SUMIFS(DATA!$D$2:$D$183,DATA!$B$2:$B$183,RESULTADOS!H12,DATA!$L$2:$L$183,RESULTADOS!$C$6) -> 4 | I16: =SUMIFS(DATA!$D$2:$D$183,DATA!$B$2:$B$183,RESULTADOS!I12,DATA!$L$2:$L$183,RESULTADOS!$C$6) -> 133 | J16: =SUMIFS(DATA!$D$2:$D$183,DATA!$B$2:$B$183,RESULTADOS!J12,DATA!$L$2:$L$183,RESULTADOS!$C$6) -> 20 | K16: =SUMIFS(DATA!$D$2:$D$183,DATA!$B$2:$B$183,RESULTADOS!K12,DATA!$L$2:$L$183,RESULTADOS!$C$6) -> 0 | L16: =SUM(C16:K16) -> 227
B17: AVERIAS | C17: =COUNTIFS(DATA!$B$2:$B$183,RESULTADOS!C12,DATA!$L$2:$L$183,RESULTADOS!$C$6,DATA!$C$2:$C$183,"<>MTTO PREVENTIVO",DATA!$C$2:$C$183,"<>REP. PLANIFICADO") -> 2 | D17: =COUNTIFS(DATA!$B$2:$B$183,RESULTADOS!D12,DATA!$L$2:$L$183,RESULTADOS!$C$6,DATA!$C$2:$C$183,"<>MTTO PREVENTIVO",DATA!$C$2:$C$183,"<>REP. PLANIFICADO") -> 1 | E17: =COUNTIFS(DATA!$B$2:$B$183,RESULTADOS!E12,DATA!$L$2:$L$183,RESULTADOS!$C$6,DATA!$C$2:$C$183,"<>MTTO PREVENTIVO",DATA!$C$2:$C$183,"<>REP. PLANIFICADO") -> 0 | F17: =COUNTIFS(DATA!$B$2:$B$183,RESULTADOS!F12,DATA!$L$2:$L$183,RESULTADOS!$C$6,DATA!$C$2:$C$183,"<>MTTO PREVENTIVO",DATA!$C$2:$C$183,"<>REP. PLANIFICADO") -> 5 | G17: =COUNTIFS(DATA!$B$2:$B$183,RESULTADOS!G12,DATA!$L$2:$L$183,RESULTADOS!$C$6,DATA!$C$2:$C$183,"<>MTTO PREVENTIVO",DATA!$C$2:$C$183,"<>REP. PLANIFICADO") -> 2 | H17: =COUNTIFS(DATA!$B$2:$B$183,RESULTADOS!H12,DATA!$L$2:$L$183,RESULTADOS!$C$6,DATA!$C$2:$C$183,"<>MTTO PREVENTIVO",DATA!$C$2:$C$183,"<>REP. PLANIFICADO") -> 0 | I17: =COUNTIFS(DATA!$B$2:$B$183,RESULTADOS!I12,DATA!$L$2:$L$183,RESULTADOS!$C$6,DATA!$C$2:$C$183,"<>MTTO PREVENTIVO",DATA!$C$2:$C$183,"<>REP. PLANIFICADO") -> 3 | J17: =COUNTIFS(DATA!$B$2:$B$183,RESULTADOS!J12,DATA!$L$2:$L$183,RESULTADOS!$C$6,DATA!$C$2:$C$183,"<>MTTO PREVENTIVO",DATA!$C$2:$C$183,"<>REP. PLANIFICADO") -> 2 | K17: =COUNTIFS(DATA!$B$2:$B$183,RESULTADOS!K12,DATA!$L$2:$L$183,RESULTADOS!$C$6,DATA!$C$2:$C$183,"<>MTTO PREVENTIVO",DATA!$C$2:$C$183,"<>REP. PLANIFICADO") -> 0 | L17: =SUM(C17:K17) -> 15
B18: OPERACIÓN REAL | C18: =C13-C14 -> 469 | D18: =D13-D14 -> 479 | E18: =E13-E14 -> 480 | F18: =F13-F14 -> 433 | G18: =G13-G14 -> 718 | H18: =H13-H14 -> 720 | I18: =I13-I14 -> 355 | J18: =J13-J14 -> 708 | K18: =K13-K14 -> 480 | L18: =SUM(C18:K18) -> 4842
B19: DISPONIBILIDAD | C19: =C18/C13 -> 0.97708333 | D19: =D18/D13 -> 0.99791667 | E19: =E18/E13 -> 1 | F19: =F18/F13 -> 0.90208333 | G19: =G18/G13 -> 0.99722222 | H19: =H18/H13 -> 1 | I19: =I18/I13 -> 0.73958333 | J19: =J18/J13 -> 0.98333333 | K19: =K18/K13 -> 1
B35: MES | C35: DISPONIBILIDAD | D35: MTTR
B36: ENERO | F36: EQUIPO | G36: TOYOTA 5
B37: FEBRERO
B38: MARZO | F38: FALLA | G38: ACUMULADO
B39: ABRIL | C39: 0.95 | D39: 13.2 | F39: POTENCIA | G39: =SUMIFS(DATA!$D$2:$D$183,DATA!$B$2:$B$183,RESULTADOS!$G$36,DATA!$L$2:$L$183,RESULTADOS!$C$6,DATA!$C$2:$C$183,RESULTADOS!F39) -> 0
B40: MAYO | C40: 0.89 | D40: 33.8 | F40: TRACCION | G40: =SUMIFS(DATA!$D$2:$D$183,DATA!$B$2:$B$183,RESULTADOS!$G$36,DATA!$L$2:$L$183,RESULTADOS!$C$6,DATA!$C$2:$C$183,RESULTADOS!F40) -> 0
B41: JUNIO | C41: 0.95 | D41: 25.3 | F41: FRENOS | G41: =SUMIFS(DATA!$D$2:$D$183,DATA!$B$2:$B$183,RESULTADOS!$G$36,DATA!$L$2:$L$183,RESULTADOS!$C$6,DATA!$C$2:$C$183,RESULTADOS!F41) -> 0
B42: JULIO | C42: 0.95 | D42: 14.18 | F42: MASTIL | G42: =SUMIFS(DATA!$D$2:$D$183,DATA!$B$2:$B$183,RESULTADOS!$G$36,DATA!$L$2:$L$183,RESULTADOS!$C$6,DATA!$C$2:$C$183,RESULTADOS!F42) -> 0
B43: AGOSTO | C43: 0.97 | D43: 29.33 | F43: ENCENDIDO | G43: =SUMIFS(DATA!$D$2:$D$183,DATA!$B$2:$B$183,RESULTADOS!$G$36,DATA!$L$2:$L$183,RESULTADOS!$C$6,DATA!$C$2:$C$183,RESULTADOS!F43) -> 1
B44: SEPTIEMBRE | C44: 0.99 | D44: 5.21 | F44: DIRECCION | G44: =SUMIFS(DATA!$D$2:$D$183,DATA!$B$2:$B$183,RESULTADOS!$G$36,DATA!$L$2:$L$183,RESULTADOS!$C$6,DATA!$C$2:$C$183,RESULTADOS!F44) -> 0
B45: OCTUBRE | C45: 0.99 | D45: 3.08 | F45: SEGURIDAD | G45: =SUMIFS(DATA!$D$2:$D$183,DATA!$B$2:$B$183,RESULTADOS!$G$36,DATA!$L$2:$L$183,RESULTADOS!$C$6,DATA!$C$2:$C$183,RESULTADOS!F45) -> 0
B46: NOVIEMBRE | C46: 0.99 | D46: 5.18 | F46: COMBUSTIBLE | G46: =SUMIFS(DATA!$D$2:$D$183,DATA!$B$2:$B$183,RESULTADOS!$G$36,DATA!$L$2:$L$183,RESULTADOS!$C$6,DATA!$C$2:$C$183,RESULTADOS!F46) -> 0
B47: DICIEMBRE | C47: 0.96 | D47: 13.2 | F47: REFRIGERACION | G47: =SUMIFS(DATA!$D$2:$D$183,DATA!$B$2:$B$183,RESULTADOS!$G$36,DATA!$L$2:$L$183,RESULTADOS!$C$6,DATA!$C$2:$C$183,RESULTADOS!F47) -> 0
F48: SIST. HIDRAULICO | G48: =SUMIFS(DATA!$D$2:$D$183,DATA!$B$2:$B$183,RESULTADOS!$G$36,DATA!$L$2:$L$183,RESULTADOS!$C$6,DATA!$C$2:$C$183,RESULTADOS!F48) -> 0
F49: ELECTRONICO | G49: =SUMIFS(DATA!$D$2:$D$183,DATA!$B$2:$B$183,RESULTADOS!$G$36,DATA!$L$2:$L$183,RESULTADOS!$C$6,DATA!$C$2:$C$183,RESULTADOS!F49) -> 0
F61: Version 3. Ultima modificacion: | H61: 45876

Sheet ACUMULADO EQUIPOS APC
B1: JULIO | AD1: TIEMPO PLAN (hrs) | AE1: TIEMPO MUERTO (hrs) | AF1: TIEMPO REAL DISPONIBLE (hrs) | AG1: TOTAL AVERÍAS
B2: EQUIPO | C2: CATERPILLAR 1 | E2: EQUIPO | F2: TOYOTA 5 | H2: EQUIPO | I2: NISSAN 7 | K2: EQUIPO | L2: TOYOTA 8 | N2: EQUIPO | O2: TOYOTA 9 | Q2: EQUIPO | R2: TOYOTA 10 | T2: EQUIPO | U2: TOYOTA 11 | W2: EQUIPO | X2: TOYOTA 12 | Z2: EQUIPO | AA2: TOYOTA 13 | AC2: TOTAL GRAL | AD2: =RESULTADOS!L13 -> 5040 | AE2: =RESULTADOS!L14 -> 198 | AF2: =RESULTADOS!L18 -> 4842 | AG2: =RESULTADOS!L17 -> 15
B4: FALLA | C4: ACUMULADO | E4: FALLA | F4: ACUMULADO | H4: FALLA | I4: ACUMULADO | K4: FALLA | L4: ACUMULADO | N4: FALLA | O4: ACUMULADO | Q4: FALLA | R4: ACUMULADO | T4: FALLA | U4: ACUMULADO | W4: FALLA | X4: ACUMULADO | Z4: FALLA | AA4: ACUMULADO | AC4: =RESULTADOS!B12 -> EQUIPOS | AD4: {=RESULTADOS!C12:K12} -> CATERPILLAR 1 | AE4: TOYOTA 5 | AF4: NISSAN 7 | AG4: TOYOTA 8 | AH4: TOYOTA 9 | AI4: TOYOTA 10 | AJ4: TOYOTA 11 | AK4: TOYOTA 12 | AL4: TOYOTA 13 | AM4: TOTAL
B5: POTENCIA | C5: 0 | E5: POTENCIA | F5: =SUMIFS(DATA!$D$2:$D$183,DATA!$B$2:$B$183,RESULTADOS!$G$36,DATA!$L$2:$L$183,RESULTADOS!$C$6,DATA!$C$2:$C$183,RESULTADOS!E5) -> 0 | H5: POTENCIA | I5: 0 | K5: POTENCIA | L5: 0 | N5: POTENCIA | O5: 0 | Q5: POTENCIA | R5: 0 | T5: POTENCIA | U5: 0 | W5: POTENCIA | X5: 0 | Z5: POTENCIA | AA5: 0 | AC5: AVERÍAS | AD5: {=RESULTADOS!C17:K17} -> 2 | AE5: 1 | AF5: 0 | AG5: 5 | AH5: 2 | AI5: 0 | AJ5: 3 | AK5: 2 | AL5: 0 | AM5: =RESULTADOS!L17 -> 15
B6: TRACCION | C6: 0 | E6: TRACCION | F6: =SUMIFS(DATA!$D$2:$D$183,DATA!$B$2:$B$183,RESULTADOS!$G$36,DATA!$L$2:$L$183,RESULTADOS!$C$6,DATA!$C$2:$C$183,RESULTADOS!E6) -> 0 | H6: TRACCION | I6: 0 | K6: TRACCION | L6: 143 | N6: TRACCION | O6: 0 | Q6: TRACCION | R6: 24 | T6: TRACCION | U6: 0 | W6: TRACCION | X6: 0 | Z6: TRACCION | AA6: 0 | AC6: TIEMPO MUERTO | AD6: {=RESULTADOS!C14:K14} -> 11 | AE6: 1 | AF6: 0 | AG6: 47 | AH6: 2 | AI6: 0 | AJ6: 125 | AK6: 12 | AL6: 0 | AM6: =RESULTADOS!L14 -> 198
B7: FRENOS | C7: 0 | E7: FRENOS | F7: =SUMIFS(DATA!$D$2:$D$183,DATA!$B$2:$B$183,RESULTADOS!$G$36,DATA!$L$2:$L$183,RESULTADOS!$C$6,DATA!$C$2:$C$183,RESULTADOS!E7) -> 0 | H7: FRENOS | I7: 0 | K7: FRENOS | L7: 0 | N7: FRENOS | O7: 0 | Q7: FRENOS | R7: 0 | T7: FRENOS | U7: 0 | W7: FRENOS | X7: 0 | Z7: FRENOS | AA7: 0
B8: MASTIL | C8: 0 | E8: MASTIL | F8: =SUMIFS(DATA!$D$2:$D$183,DATA!$B$2:$B$183,RESULTADOS!$G$36,DATA!$L$2:$L$183,RESULTADOS!$C$6,DATA!$C$2:$C$183,RESULTADOS!E8) -> 0 | H8: MASTIL | I8: 0 | K8: MASTIL | L8: 0 | N8: MASTIL | O8: 0 | Q8: MASTIL | R8: 0 | T8: MASTIL | U8: 0 | W8: MASTIL | X8: 0 | Z8: MASTIL | AA8: 0
B9: ENCENDIDO | C9: 0 | E9: ENCENDIDO | F9: =SUMIFS(DATA!$D$2:$D$183,DATA!$B$2:$B$183,RESULTADOS!$G$36,DATA!$L$2:$L$183,RESULTADOS!$C$6,DATA!$C$2:$C$183,RESULTADOS!E9) -> 0 | H9: ENCENDIDO | I9: 0 | K9: ENCENDIDO | L9: 0 | N9: ENCENDIDO | O9: 0 | Q9: ENCENDIDO | R9: 0 | T9: ENCENDIDO | U9: 0 | W9: ENCENDIDO | X9: 0 | Z9: ENCENDIDO | AA9: 0
B10: DIRECCION | C10: 2 | E10: DIRECCION | F10: =SUMIFS(DATA!$D$2:$D$183,DATA!$B$2:$B$183,RESULTADOS!$G$36,DATA!$L$2:$L$183,RESULTADOS!$C$6,DATA!$C$2:$C$183,RESULTADOS!E10) -> 0 | H10: DIRECCION | I10: 0 | K10: DIRECCION | L10: 0 | N10: DIRECCION | O10: 0 | Q10: DIRECCION | R10: 0 | T10: DIRECCION | U10: 0 | W10: DIRECCION | X10: 2 | Z10: DIRECCION | AA10: 0
B11: SEGURIDAD | C11: 0 | E11: SEGURIDAD | F11: =SUMIFS(DATA!$D$2:$D$183,DATA!$B$2:$B$183,RESULTADOS!$G$36,DATA!$L$2:$L$183,RESULTADOS!$C$6,DATA!$C$2:$C$183,RESULTADOS!E11) -> 0 | H11: SEGURIDAD | I11: 0 | K11: SEGURIDAD | L11: 0 | N11: SEGURIDAD | O11: 0 | Q11: SEGURIDAD | R11: 0 | T11: SEGURIDAD | U11: 0 | W11: SEGURIDAD | X11: 0 | Z11: SEGURIDAD | AA11: 0
B12: COMBUSTIBLE | C12: 0 | E12: COMBUSTIBLE | F12: =SUMIFS(DATA!$D$2:$D$183,DATA!$B$2:$B$183,RESULTADOS!$G$36,DATA!$L$2:$L$183,RESULTADOS!$C$6,DATA!$C$2:$C$183,RESULTADOS!E12) -> 0 | H12: COMBUSTIBLE | I12: 0 | K12: COMBUSTIBLE | L12: 0 | N12: COMBUSTIBLE | O12: 0 | Q12: COMBUSTIBLE | R12: 0 | T12: COMBUSTIBLE | U12: 0 | W12: COMBUSTIBLE | X12: 0 | Z12: COMBUSTIBLE | AA12: 0
B13: REFRIGERACION | C13: 0 | E13: REFRIGERACION | F13: =SUMIFS(DATA!$D$2:$D$183,DATA!$B$2:$B$183,RESULTADOS!$G$36,DATA!$L$2:$L$183,RESULTADOS!$C$6,DATA!$C$2:$C$183,RESULTADOS!E13) -> 0 | H13: REFRIGERACION | I13: 0 | K13: REFRIGERACION | L13: 0 | N13: REFRIGERACION | O13: 0 | Q13: REFRIGERACION | R13: 0 | T13: REFRIGERACION | U13: 0 | W13: REFRIGERACION | X13: 0 | Z13: REFRIGERACION | AA13: 0
B14: SIST. HIDRAULICO | C14: 0 | E14: SIST. HIDRAULICO | F14: =SUMIFS(DATA!$D$2:$D$183,DATA!$B$2:$B$183,RESULTADOS!$G$36,DATA!$L$2:$L$183,RESULTADOS!$C$6,DATA!$C$2:$C$183,RESULTADOS!E14) -> 0 | H14: SIST. HIDRAULICO | I14: 0 | K14: SIST. HIDRAULICO | L14: 0 | N14: SIST. HIDRAULICO | O14: 0 | Q14: SIST. HIDRAULICO | R14: 0 | T14: SIST. HIDRAULICO | U14: 0 | W14: SIST. HIDRAULICO | X14: 0 | Z14: SIST. HIDRAULICO | AA14: 0
H15: ELECTRONICO | I15: 0 | Z15: ELECTRONICO | AA15: 5

Sheet LISTA
A1: EQUIPO | B1: SISTEMA | C1: RUTINA DE PREVENTIVO | D1: PROCESO
A2: CATERPILLAR 1 | B2: FRENOS | C2: M1 (250) | D2: FACTURADO
A3: TOYOTA 5 | B3: POTENCIA | C3: M2 (1000) | D3: SOLPED
A4: NISSAN 7 | B4: TRACCION | C4: M3 (2000)
A5: TOYOTA 8 | B5: SEGURIDAD | C5: OH (OVERHAUL)
A6: TOYOTA 9 | B6: ENCENDIDO
A7: TOYOTA 10 | B7: REFRIGERACION
A8: TOYOTA 11 | B8: MASTIL
A9: TOYOTA 12 | B9: DIRECCION
A10: TOYOTA 13 | B10: COMBUSTIBLE
B11: SIST. HIDRAULICO
B12: MTTO PREVENTIVO
B13: ELECTRONICO
B14: REP. PLANIFICADO
